<?xml version="1.0" ?>
<sdf version="1.7">
<model name='freenove_4wd'>
  <pose>0 0 0 0 0 0</pose>

  <link name='base_link'>
    <inertial>
        <mass>0.2</mass>
        <inertia>
          <ixx>0.01</ixx>
          <iyy>0.01</iyy>
          <izz>0.01</izz>
        </inertia>
      </inertial>

    <visual name='chassis_visual'>
        <pose>0 0 0 0 0 0</pose>
        <geometry>
          <box>
            <size>0.2 0.1 0.03</size>
          </box>
        </geometry>
        <material>
          <diffuse>0.05 0.05 0.05 1</diffuse>
          <specular>0.8 0.8 0.8 1</specular>
        </material>
      </visual>

      <collision name='chassis_collision'>
        <pose>0 0 0 0 0 0</pose>
        <geometry>
          <box>
            <size>0.2 0.1 0.03</size>
          </box>
        </geometry>
      </collision>

    <visual name='computer_visual'>
        <pose>-0.05 0 0.03 0 0 0</pose>
        <geometry>
          <box>
            <size>0.1 0.07 0.01</size>
          </box>
        </geometry>
        <material>
          <diffuse>0 0.2 0 1</diffuse>
          <specular>0.8 0.8 0.8 1</specular>
        </material>
      </visual>

      <collision name='computer_collision'>
        <pose>-0.05 0 0.03 0 0 0</pose>
        <geometry>
          <box>
            <size>0.1 0.07 0.01</size>
          </box>
        </geometry>
      </collision>

  </link>
  <link name="front_left">
    <pose>0.08 0.07 -0.01 -1.5707 0 0</pose>
    <inertial>
        <mass>0.005</mass>
        <inertia>
          <ixx>0.0001</ixx>
          <iyy>0.0001</iyy>
          <izz>0.0001</izz>
        </inertia>
      </inertial>

    <collision name="collision">
      <geometry>
        <cylinder>
          <radius>0.03</radius>
          <length>0.02</length>
        </cylinder>
      </geometry>
    </collision>

    <visual name="tire">
      <geometry>
        <cylinder>
          <radius>0.03</radius>
          <length>0.02</length>
        </cylinder>
      </geometry>
      <material>
        <diffuse>0 0 0 1</diffuse>
        <specular>0.2 0.2 0.2 1</specular>
      </material>
    </visual>

    <visual name="wheel">
      <geometry>
        <cylinder>
          <radius>0.028499999999999998</radius>
          <length>0.022</length>
        </cylinder>
      </geometry>
      <material>
        <diffuse>0.02 0.02 0.02 1</diffuse>
        <specular>0.8 0.8 0.8 1</specular>
      </material>
    </visual>

    <visual name="wheel_line">
      <geometry>
        <box>
          <size>0.053 0.01 0.024</size>
        </box>
      </geometry>
      <material>
        <diffuse>0.5 0.5 0.5 1</diffuse>
        <specular>0.8 0.8 0.8 1</specular>
      </material>
    </visual>

    <visual name="wheel_line2">
      <geometry>
        <box>
          <size>0.01 0.053 0.024</size>
        </box>
      </geometry>
      <material>
        <diffuse>0.5 0.5 0.5 1</diffuse>
        <specular>0.8 0.8 0.8 1</specular>
      </material>
    </visual>

  </link>

  <joint type="revolute" name="front_left_joint">
    <child>front_left</child>
    <parent>base_link</parent>
    <axis>
      <xyz>0 0 1</xyz>
      <dynamics>
        <friction>0.01</friction>
        <damping>0.01</damping>
      </dynamics>
    </axis>
  </joint>
  
  <link name="front_right">
    <pose>0.08 -0.07 -0.01 -1.5707 0 0</pose>
    <inertial>
        <mass>0.005</mass>
        <inertia>
          <ixx>0.0001</ixx>
          <iyy>0.0001</iyy>
          <izz>0.0001</izz>
        </inertia>
      </inertial>

    <collision name="collision">
      <geometry>
        <cylinder>
          <radius>0.03</radius>
          <length>0.02</length>
        </cylinder>
      </geometry>
    </collision>

    <visual name="tire">
      <geometry>
        <cylinder>
          <radius>0.03</radius>
          <length>0.02</length>
        </cylinder>
      </geometry>
      <material>
        <diffuse>0 0 0 1</diffuse>
        <specular>0.2 0.2 0.2 1</specular>
      </material>
    </visual>

    <visual name="wheel">
      <geometry>
        <cylinder>
          <radius>0.028499999999999998</radius>
          <length>0.022</length>
        </cylinder>
      </geometry>
      <material>
        <diffuse>0.02 0.02 0.02 1</diffuse>
        <specular>0.8 0.8 0.8 1</specular>
      </material>
    </visual>

    <visual name="wheel_line">
      <geometry>
        <box>
          <size>0.053 0.01 0.024</size>
        </box>
      </geometry>
      <material>
        <diffuse>0.5 0.5 0.5 1</diffuse>
        <specular>0.8 0.8 0.8 1</specular>
      </material>
    </visual>

    <visual name="wheel_line2">
      <geometry>
        <box>
          <size>0.01 0.053 0.024</size>
        </box>
      </geometry>
      <material>
        <diffuse>0.5 0.5 0.5 1</diffuse>
        <specular>0.8 0.8 0.8 1</specular>
      </material>
    </visual>

  </link>

  <joint type="revolute" name="front_right_joint">
    <child>front_right</child>
    <parent>base_link</parent>
    <axis>
      <xyz>0 0 1</xyz>
      <dynamics>
        <friction>0.01</friction>
        <damping>0.01</damping>
      </dynamics>
    </axis>
  </joint>
  
  <link name="rear_left">
    <pose>-0.08 0.07 -0.01 -1.5707 0 0</pose>
    <inertial>
        <mass>0.005</mass>
        <inertia>
          <ixx>0.0001</ixx>
          <iyy>0.0001</iyy>
          <izz>0.0001</izz>
        </inertia>
      </inertial>

    <collision name="collision">
      <geometry>
        <cylinder>
          <radius>0.03</radius>
          <length>0.02</length>
        </cylinder>
      </geometry>
    </collision>

    <visual name="tire">
      <geometry>
        <cylinder>
          <radius>0.03</radius>
          <length>0.02</length>
        </cylinder>
      </geometry>
      <material>
        <diffuse>0 0 0 1</diffuse>
        <specular>0.2 0.2 0.2 1</specular>
      </material>
    </visual>

    <visual name="wheel">
      <geometry>
        <cylinder>
          <radius>0.028499999999999998</radius>
          <length>0.022</length>
        </cylinder>
      </geometry>
      <material>
        <diffuse>0.02 0.02 0.02 1</diffuse>
        <specular>0.8 0.8 0.8 1</specular>
      </material>
    </visual>

    <visual name="wheel_line">
      <geometry>
        <box>
          <size>0.053 0.01 0.024</size>
        </box>
      </geometry>
      <material>
        <diffuse>0.5 0.5 0.5 1</diffuse>
        <specular>0.8 0.8 0.8 1</specular>
      </material>
    </visual>

    <visual name="wheel_line2">
      <geometry>
        <box>
          <size>0.01 0.053 0.024</size>
        </box>
      </geometry>
      <material>
        <diffuse>0.5 0.5 0.5 1</diffuse>
        <specular>0.8 0.8 0.8 1</specular>
      </material>
    </visual>

  </link>

  <joint type="revolute" name="rear_left_joint">
    <child>rear_left</child>
    <parent>base_link</parent>
    <axis>
      <xyz>0 0 1</xyz>
      <dynamics>
        <friction>0.01</friction>
        <damping>0.01</damping>
      </dynamics>
    </axis>
  </joint>
  
  <link name="rear_right">
    <pose>-0.08 -0.07 -0.01 -1.5707 0 0</pose>
    <inertial>
        <mass>0.005</mass>
        <inertia>
          <ixx>0.0001</ixx>
          <iyy>0.0001</iyy>
          <izz>0.0001</izz>
        </inertia>
      </inertial>

    <collision name="collision">
      <geometry>
        <cylinder>
          <radius>0.03</radius>
          <length>0.02</length>
        </cylinder>
      </geometry>
    </collision>

    <visual name="tire">
      <geometry>
        <cylinder>
          <radius>0.03</radius>
          <length>0.02</length>
        </cylinder>
      </geometry>
      <material>
        <diffuse>0 0 0 1</diffuse>
        <specular>0.2 0.2 0.2 1</specular>
      </material>
    </visual>

    <visual name="wheel">
      <geometry>
        <cylinder>
          <radius>0.028499999999999998</radius>
          <length>0.022</length>
        </cylinder>
      </geometry>
      <material>
        <diffuse>0.02 0.02 0.02 1</diffuse>
        <specular>0.8 0.8 0.8 1</specular>
      </material>
    </visual>

    <visual name="wheel_line">
      <geometry>
        <box>
          <size>0.053 0.01 0.024</size>
        </box>
      </geometry>
      <material>
        <diffuse>0.5 0.5 0.5 1</diffuse>
        <specular>0.8 0.8 0.8 1</specular>
      </material>
    </visual>

    <visual name="wheel_line2">
      <geometry>
        <box>
          <size>0.01 0.053 0.024</size>
        </box>
      </geometry>
      <material>
        <diffuse>0.5 0.5 0.5 1</diffuse>
        <specular>0.8 0.8 0.8 1</specular>
      </material>
    </visual>

  </link>

  <joint type="revolute" name="rear_right_joint">
    <child>rear_right</child>
    <parent>base_link</parent>
    <axis>
      <xyz>0 0 1</xyz>
      <dynamics>
        <friction>0.01</friction>
        <damping>0.01</damping>
      </dynamics>
    </axis>
  </joint>
  

  

  <!--<plugin name='p3d' filename='libgazebo_ros_p3d.so'>-->
    <!--<robotNamespace>freenove_4wd</robotNamespace>-->
    <!--<updateRate>10</updateRate>-->
    <!--<bodyName>base_link</bodyName>-->
    <!--<topicName>/qualisys/freenove_4wd/odom</topicName>-->
    <!--<frameName>map</frameName>-->
    <!--<xyzOffset>0 0 0</xyzOffset>-->
    <!--<rpyOffset>0 0 0</rpyOffset>-->
  <!--</plugin>-->

  <!--<plugin name="skid_steer_drive_controller" filename="libgazebo_ros_skid_steer_drive.so">-->
    <!--<robotNamespace>freenove_4wd</robotNamespace>-->
    <!--<updateRate>100.0</updateRate>-->
    <!--<leftFrontJoint>front_left_joint</leftFrontJoint>-->
    <!--<rightFrontJoint>front_right_joint</rightFrontJoint>-->
    <!--<leftRearJoint>rear_left_joint</leftRearJoint>-->
    <!--<rightRearJoint>rear_right_joint</rightRearJoint>-->
    <!--<wheelSeparation>0.14</wheelSeparation>-->
    <!--<wheelDiameter>0.06</wheelDiameter>-->
    <!--<robotBaseFrame>rover_ground_truth</robotBaseFrame>-->
    <!--<torque>0.3</torque>-->
    <!--<broadcastTF>false</broadcastTF>-->
    <!--<commandTopic>cmd_vel</commandTopic>-->
    <!--<odometryTopic>odom</odometryTopic>-->
    <!--<odometryFrame>map</odometryFrame>-->
    <!--<covariance_x>0.0001</covariance_x>-->
    <!--<covariance_y>0.0001</covariance_y>-->
    <!--<covariance_yaw>0.0001</covariance_yaw>-->
  <!--</plugin>-->
</model>

</sdf>
<!-- vim: set et fenc=utf-8 ff=unix sts=0 sw=2 ts=2 : -->