<?xml version="1.0" ?>
<!-- DO NOT EDIT: Generated from px4vision.sdf.jinja -->
<sdf version="1.7">
<model name="px4vision">
  <pose>0 0 0 0 0 0</pose>

  <link name="base_link">
    <inertial>
        <mass>1.5</mass>
        <inertia>
          <ixx>0.029125</ixx> <iyy>0.029125</iyy>
          <izz>0.055225</izz>
        </inertia>
      </inertial>

    <visual name="fuselage_visual">
      <geometry>
        <mesh>
          <uri>model://px4vision/meshes/px4vision.stl</uri>
        </mesh>
      </geometry>
      <material>
        <diffuse>0 0 0 1</diffuse>
        <specular>0.5 0.5 0.5 1</specular>
      </material>
    </visual>

    <collision name="fuselage_collision">
      <geometry>
          <box>
            <size>0.2 0.2 0.13</size>
          </box>
        </geometry>
      <surface>
        <contact>
          <ode>
            <min_depth>1e-3</min_depth>
            <max_vel>0.1</max_vel>
            <kp>1e4</kp>
            <kd>1e1</kd>
          </ode>
        </contact>
        <friction>
          <ode/>
        </friction>
      </surface>
    </collision>

    <collision name="mast_collision">
      <pose>0.06 0 0.11 0 0 0</pose>
      <geometry>
          <cylinder>
            <radius>0.03</radius>
            <length>0.1</length>
          </cylinder>
        </geometry>
    </collision>

    <sensor name="imu_sensor" type="imu">
        <always_on>1</always_on>
        <update_rate>250</update_rate>
        <visualize>true</visualize>
        <topic>imu</topic>
    </sensor>

    <sensor name="realsense_d435" type="rgbd_camera">
      <pose>0.09 0 -0.01 0 0 0</pose>
      <camera>
        <horizontal_fov>1.20428</horizontal_fov>
        <image>
          <format>R8G8B8</format>
          <width>640</width>
          <height>480</height>
        </image>
        <clip>
          <near>0.1</near>
          <far>100</far>
        </clip>
      </camera>
      <always_on>1</always_on>
      <update_rate>15</update_rate>
      <visualize>1</visualize>
      <topic>rgbd_camera</topic>
      <enable_metrics>true</enable_metrics>
    </sensor>

    <!--https://www.digikey.com/catalog/en/partgroup/psk-cm8jl65-cc5-tof-infrared-distance-measuring-sensor/90142-->
    <!--<sensor name="laser" type="ray">-->
      <!--<pose>0 0 0 0 1.57079633 0</pose>-->
      <!--<always_on>1</always_on>-->
      <!--<update_rate>20</update_rate>-->
      <!--<visualize>true</visualize>-->
      <!--<ray>-->
        <!--<scan>-->
          <!--<horizontal>-->
            <!--<samples>1</samples>-->
            <!--<resolution>1</resolution>-->
            <!--<min_angle>-0</min_angle>-->
            <!--<max_angle>0</max_angle>-->
          <!--</horizontal>-->
        <!--</scan>-->
        <!--<range>-->
          <!--<min>0.18</min>-->
          <!--<max>8.0</max>-->
          <!--<resolution>0.001</resolution>-->
        <!--</range>-->
        <!--<noise>-->
          <!--<type>gaussian</type>-->
          <!--<mean>0.0</mean>-->
          <!--<stddev>0.02</stddev>-->
        <!--</noise>-->
      <!--</ray>-->
      <!--<plugin name="laser_altimeter_plugin" filename="libgazebo_lidar_plugin.so">-->
        <!--<robotNamespace></robotNamespace>-->
        <!--<topic>/lidar</topic>-->
        <!--<min_distance>0.17</min_distance>-->
        <!--<max_distance>8.0</max_distance>-->
      <!--</plugin>-->
    <!--</sensor>-->

    <!--<sensor name="gps" type="gps">-->
      <!--<pose>0 0 0 0 0 0</pose>-->
      <!--<update_rate>5.0</update_rate>-->
      <!--<always_on>true</always_on>-->
      <!--<visualize>false</visualize>-->
      <!--<plugin name="gps_plugin" filename="libgazebo_gps_plugin.so">-->
        <!--<robotNamespace></robotNamespace>-->
        <!--<topic>/gps</topic>-->
        <!--<gpsNoise>true</gpsNoise>-->
        <!--<gpsXYRandomWalk>2.0</gpsXYRandomWalk>-->
        <!--<gpsZRandomWalk>4.0</gpsZRandomWalk>-->
        <!--<gpsXYNoiseDensity>2.0e-4</gpsXYNoiseDensity>-->
        <!--<gpsZNoiseDensity>4.0e-4</gpsZNoiseDensity>-->
        <!--<gpsVXYNoiseDensity>0.2</gpsVXYNoiseDensity>-->
        <!--<gpsVZNoiseDensity>0.4</gpsVZNoiseDensity>-->
      <!--</plugin>-->
    <!--</sensor>--></link>

  <!--<plugin name='p3d' filename='libgazebo_ros_p3d.so'>-->
    <!--<robotNamespace>px4vision</robotNamespace>-->
    <!--<updateRate>10</updateRate>-->
    <!--<bodyName>base_link</bodyName>-->
    <!--<topicName>/qualisys/px4vision/odom</topicName>-->
    <!--<frameName>map</frameName>-->
    <!--<xyzOffset>0 0 0</xyzOffset>-->
    <!--<rpyOffset>0 0 0</rpyOffset>-->
  <!--</plugin>-->

  <!--<plugin name='magnetometer_plugin' filename='libgazebo_magnetometer_plugin.so'>-->
    <!--<robotNamespace/>-->
    <!--<pubRate>100</pubRate>-->
    <!--<noiseDensity>0.0004</noiseDensity>-->
    <!--<randomWalk>6.4e-06</randomWalk>-->
    <!--<biasCorrelationTime>600</biasCorrelationTime>-->
    <!--<magTopic>/mag</magTopic>-->
  <!--</plugin>-->

  <!--<plugin-->
    <!--filename="libgazebo_barometer_plugin.so"-->
    <!--name="barometer_plugin::BarometerPlugin">-->
    <!--<linkName>base_link</linkName>-->
    <!--<robotNamespace/>-->
    <!--<pubRate>50</pubRate>-->
    <!--<baroTopic>/baro</baroTopic>-->
    <!--<baroDriftPaPerSec>0</baroDriftPaPerSec>-->
  <!--</plugin>-->

  <plugin
    filename="libgazebo_barometer_plugin.so"
    name="barometer_plugin::BarometerPlugin">
    <link_name>base_link</link_name>
  </plugin>
  <plugin
    filename="libgazebo_magnetometer_plugin.so"
    name="magnetometer_plugin::MagnetometerPlugin">
    <link_name>base_link</link_name>
  </plugin>
  <plugin
    filename="libgazebo_gps_plugin.so"
    name="gps_plugin::GpsPlugin">
    <link_name>base_link</link_name>
  </plugin>

  <plugin
    filename="libmavlink_sitl_ign_gazebo.so"
    name="mavlink_interface::GazeboMavlinkInterface">
    <robotNamespace/>
    <imuSubTopic>/imu</imuSubTopic>
    <magSubTopic>/mag</magSubTopic>
    <baroSubTopic>/baro</baroSubTopic>
    <opticalFlowSubTopic>/opticalFlow</opticalFlowSubTopic>
    <mavlink_addr>INADDR_ANY</mavlink_addr>
    <mavlink_tcp_port>4560</mavlink_tcp_port>
    <mavlink_udp_port>14560</mavlink_udp_port>
    <serialEnabled>0</serialEnabled>
    <serialDevice>/dev/ttyACM0</serialDevice>
    <baudRate>921600</baudRate>
    <qgc_addr>INADDR_ANY</qgc_addr>
    <qgc_udp_port>14550</qgc_udp_port>
    <sdk_addr>INADDR_ANY</sdk_addr>
    <sdk_udp_port>14540</sdk_udp_port>
    <hil_mode>0</hil_mode>
    <hil_state_level>0</hil_state_level>
    <send_vision_estimation>0</send_vision_estimation>
    <send_odometry>0</send_odometry>
    <enable_lockstep>1</enable_lockstep>
    <use_tcp>1</use_tcp>
    <motorSpeedCommandPubTopic>/command/motor_speed</motorSpeedCommandPubTopic>
    <control_channels><channel name='rotor1'>
        <input_index>0</input_index>
        <input_offset>0</input_offset>
        <input_scaling>1000</input_scaling>
        <zero_position_disarmed>0</zero_position_disarmed>
        <zero_position_armed>100</zero_position_armed>
        <joint_control_type>velocity</joint_control_type>
      </channel>
      <channel name='rotor2'>
        <input_index>1</input_index>
        <input_offset>0</input_offset>
        <input_scaling>1000</input_scaling>
        <zero_position_disarmed>0</zero_position_disarmed>
        <zero_position_armed>100</zero_position_armed>
        <joint_control_type>velocity</joint_control_type>
      </channel>
      <channel name='rotor3'>
        <input_index>2</input_index>
        <input_offset>0</input_offset>
        <input_scaling>1000</input_scaling>
        <zero_position_disarmed>0</zero_position_disarmed>
        <zero_position_armed>100</zero_position_armed>
        <joint_control_type>velocity</joint_control_type>
      </channel>
      <channel name='rotor4'>
        <input_index>3</input_index>
        <input_offset>0</input_offset>
        <input_scaling>1000</input_scaling>
        <zero_position_disarmed>0</zero_position_disarmed>
        <zero_position_armed>100</zero_position_armed>
        <joint_control_type>velocity</joint_control_type>
      </channel>
      
    </control_channels>
  </plugin>

  <!--Rotor 0 -->
  <link name="rotor_0">

    <pose>0.091 -0.108 0.032 0 0 0</pose>
    <inertial>
          <mass>0.005</mass>
          <inertia>
            <ixx>9.75e-07</ixx> <iyy>0.000273104</iyy>
            <izz>0.000274004</izz>
          </inertia>
        </inertial>
    <visual name="rotor_0_visual">
      <geometry>
        <mesh>
          <uri>model://px4vision/meshes/prop_ccw.stl</uri>
        </mesh>
      </geometry>
      <material>
        <diffuse>0 0 0 1</diffuse>
        <specular>0.2 0.2 0.2 1</specular>
      </material>
    </visual>

    <collision name="rotor_0_collision">
      <geometry>
          <cylinder>
            <radius>0.08</radius>
            <length>0.001</length>
          </cylinder>
        </geometry>
    </collision>

  </link>

  <joint name="rotor_0_joint" type="revolute">
    <parent>base_link</parent>
    <child>rotor_0</child>
    <axis>
      <xyz>0 0 1</xyz>
      <limit>
        <lower>-1e+16</lower>
        <upper>1e+16</upper>
      </limit>
      <use_parent_model_frame>1</use_parent_model_frame>
    </axis>
  </joint>

  <plugin 
    filename="ignition-gazebo-multicopter-motor-model-system"
    name="ignition::gazebo::systems::MulticopterMotorModel">
    <robotNamespace/>
    <jointName>rotor_0_joint</jointName>
    <linkName>rotor_0</linkName>
    <turningDirection>ccw</turningDirection>
    <timeConstantUp>0.0125</timeConstantUp>
    <timeConstantDown>0.025</timeConstantDown>
    <maxRotVelocity>1100</maxRotVelocity>
    <motorConstant>5.84e-06</motorConstant>
    <momentConstant>0.06</momentConstant>
    <commandSubTopic>/command/motor_speed</commandSubTopic>
    <motorNumber>0</motorNumber>
    <rotorDragCoefficient>0.000175</rotorDragCoefficient>
    <rollingMomentCoefficient>1e-06</rollingMomentCoefficient>
    <motorSpeedPubTopic>/motor_speed/0</motorSpeedPubTopic>
    <rotorVelocitySlowdownSim>10</rotorVelocitySlowdownSim>
  </plugin>
  

  <!--Rotor 1 -->
  <link name="rotor_1">

    <pose>-0.097 0.108 0.032 0 0 0</pose>
    <inertial>
          <mass>0.005</mass>
          <inertia>
            <ixx>9.75e-07</ixx> <iyy>0.000273104</iyy>
            <izz>0.000274004</izz>
          </inertia>
        </inertial>
    <visual name="rotor_1_visual">
      <geometry>
        <mesh>
          <uri>model://px4vision/meshes/prop_ccw.stl</uri>
        </mesh>
      </geometry>
      <material>
        <diffuse>0 0 0 1</diffuse>
        <specular>0.2 0.2 0.2 1</specular>
      </material>
    </visual>

    <collision name="rotor_1_collision">
      <geometry>
          <cylinder>
            <radius>0.08</radius>
            <length>0.001</length>
          </cylinder>
        </geometry>
    </collision>

  </link>

  <joint name="rotor_1_joint" type="revolute">
    <parent>base_link</parent>
    <child>rotor_1</child>
    <axis>
      <xyz>0 0 1</xyz>
      <limit>
        <lower>-1e+16</lower>
        <upper>1e+16</upper>
      </limit>
      <use_parent_model_frame>1</use_parent_model_frame>
    </axis>
  </joint>

  <plugin 
    filename="ignition-gazebo-multicopter-motor-model-system"
    name="ignition::gazebo::systems::MulticopterMotorModel">
    <robotNamespace/>
    <jointName>rotor_1_joint</jointName>
    <linkName>rotor_1</linkName>
    <turningDirection>ccw</turningDirection>
    <timeConstantUp>0.0125</timeConstantUp>
    <timeConstantDown>0.025</timeConstantDown>
    <maxRotVelocity>1100</maxRotVelocity>
    <motorConstant>5.84e-06</motorConstant>
    <momentConstant>0.06</momentConstant>
    <commandSubTopic>/command/motor_speed</commandSubTopic>
    <motorNumber>1</motorNumber>
    <rotorDragCoefficient>0.000175</rotorDragCoefficient>
    <rollingMomentCoefficient>1e-06</rollingMomentCoefficient>
    <motorSpeedPubTopic>/motor_speed/1</motorSpeedPubTopic>
    <rotorVelocitySlowdownSim>10</rotorVelocitySlowdownSim>
  </plugin>
  

  <!--Rotor 2 -->
  <link name="rotor_2">

    <pose>0.091 0.108 0.032 0 0 0</pose>
    <inertial>
          <mass>0.005</mass>
          <inertia>
            <ixx>9.75e-07</ixx> <iyy>0.000273104</iyy>
            <izz>0.000274004</izz>
          </inertia>
        </inertial>
    <visual name="rotor_2_visual">
      <geometry>
        <mesh>
          <uri>model://px4vision/meshes/prop_cw.stl</uri>
        </mesh>
      </geometry>
      <material>
        <diffuse>0 0 0 1</diffuse>
        <specular>0.2 0.2 0.2 1</specular>
      </material>
    </visual>

    <collision name="rotor_2_collision">
      <geometry>
          <cylinder>
            <radius>0.08</radius>
            <length>0.001</length>
          </cylinder>
        </geometry>
    </collision>

  </link>

  <joint name="rotor_2_joint" type="revolute">
    <parent>base_link</parent>
    <child>rotor_2</child>
    <axis>
      <xyz>0 0 1</xyz>
      <limit>
        <lower>-1e+16</lower>
        <upper>1e+16</upper>
      </limit>
      <use_parent_model_frame>1</use_parent_model_frame>
    </axis>
  </joint>

  <plugin 
    filename="ignition-gazebo-multicopter-motor-model-system"
    name="ignition::gazebo::systems::MulticopterMotorModel">
    <robotNamespace/>
    <jointName>rotor_2_joint</jointName>
    <linkName>rotor_2</linkName>
    <turningDirection>cw</turningDirection>
    <timeConstantUp>0.0125</timeConstantUp>
    <timeConstantDown>0.025</timeConstantDown>
    <maxRotVelocity>1100</maxRotVelocity>
    <motorConstant>5.84e-06</motorConstant>
    <momentConstant>0.06</momentConstant>
    <commandSubTopic>/command/motor_speed</commandSubTopic>
    <motorNumber>2</motorNumber>
    <rotorDragCoefficient>0.000175</rotorDragCoefficient>
    <rollingMomentCoefficient>1e-06</rollingMomentCoefficient>
    <motorSpeedPubTopic>/motor_speed/2</motorSpeedPubTopic>
    <rotorVelocitySlowdownSim>10</rotorVelocitySlowdownSim>
  </plugin>
  

  <!--Rotor 3 -->
  <link name="rotor_3">

    <pose>-0.097 -0.108 0.032 0 0 0</pose>
    <inertial>
          <mass>0.005</mass>
          <inertia>
            <ixx>9.75e-07</ixx> <iyy>0.000273104</iyy>
            <izz>0.000274004</izz>
          </inertia>
        </inertial>
    <visual name="rotor_3_visual">
      <geometry>
        <mesh>
          <uri>model://px4vision/meshes/prop_cw.stl</uri>
        </mesh>
      </geometry>
      <material>
        <diffuse>0 0 0 1</diffuse>
        <specular>0.2 0.2 0.2 1</specular>
      </material>
    </visual>

    <collision name="rotor_3_collision">
      <geometry>
          <cylinder>
            <radius>0.08</radius>
            <length>0.001</length>
          </cylinder>
        </geometry>
    </collision>

  </link>

  <joint name="rotor_3_joint" type="revolute">
    <parent>base_link</parent>
    <child>rotor_3</child>
    <axis>
      <xyz>0 0 1</xyz>
      <limit>
        <lower>-1e+16</lower>
        <upper>1e+16</upper>
      </limit>
      <use_parent_model_frame>1</use_parent_model_frame>
    </axis>
  </joint>

  <plugin 
    filename="ignition-gazebo-multicopter-motor-model-system"
    name="ignition::gazebo::systems::MulticopterMotorModel">
    <robotNamespace/>
    <jointName>rotor_3_joint</jointName>
    <linkName>rotor_3</linkName>
    <turningDirection>cw</turningDirection>
    <timeConstantUp>0.0125</timeConstantUp>
    <timeConstantDown>0.025</timeConstantDown>
    <maxRotVelocity>1100</maxRotVelocity>
    <motorConstant>5.84e-06</motorConstant>
    <momentConstant>0.06</momentConstant>
    <commandSubTopic>/command/motor_speed</commandSubTopic>
    <motorNumber>3</motorNumber>
    <rotorDragCoefficient>0.000175</rotorDragCoefficient>
    <rollingMomentCoefficient>1e-06</rollingMomentCoefficient>
    <motorSpeedPubTopic>/motor_speed/3</motorSpeedPubTopic>
    <rotorVelocitySlowdownSim>10</rotorVelocitySlowdownSim>
  </plugin>
  

</model>
</sdf>
<!-- vim: set et ft=xml fenc=utf-8 ff=unix sts=0 sw=2 ts=2 : -->